<?xml version="1.0"?>
<robot name="plane" xmlns:xacro="http://www.ros.org/wiki/xacro">

 
    <material name="weird">
	    <color rgba="0.5 0.5 0.8 1"/>
    </material>


    <link name="world">
        
    </link>

    <joint name="world_joint" type="fixed">
        <origin xyz="0 0 0.5" rpy="0 0 0" />
        <parent link="world" />
        <child link="plane" />
    </joint>

    <link name="plane">
    
    </link>   
    
    
    <joint name="imu_joint" type="floating">
        <origin xyz="0 0 0" rpy="0 0 0" />
        <parent link="plane" />
        <child link="imu_link" />
    </joint>

    <link name="imu_link">
      <visual>
        <origin rpy="1.57 0 0" xyz="-0.6 0.5 0"/>
        <geometry>
          <mesh filename="package://my_robot_description/meshes/basic_plane_2.STL" scale="0.01 0.01 0.01"/> 
        </geometry>
        <material name="weird"/>
      </visual>
    </link>   

</robot>
